Workbook

Sheet Data Clean Excel
A1: Order_ID | B1: Order_ID | C1: First_Name | F1: Last_Name | G1: City | H1: Product | I1: Region | J1: Email | L1: Phone | M1: Order_Date_Raw | N1: Quantity | O1: Unit_Price | P1: Unit_Price | Q1: Sales_Channel | R1: Notes | T1: year | U1: Month | V1: Day
A2: ORD-1001 | B2: =LEFT(A2,3) -> ORD | C2: Usman | D2: =CLEAN(TRIM(C2)) -> Usman | E2: =PROPER(TRIM(C2)) -> Usman | F2: Siddiqui | G2: Sukkur | H2: Mouse | I2: West | J2: usman36@example.com | K2: =TRIM(IF(J2="","",SUBSTITUTE(SUBSTITUTE(SUBSTITUTE(TRIM(J2),"@@","@"),"..","."),"milto:",""))) -> usman36@example.com | M2: 01/10/2026 | N2: 3 | O2: 7500 | P2: =SUBSTITUTE(SUBSTITUTE(SUBSTITUTE(O2,"K","000"),"m","000000"),"RS.","") -> 7500 | Q2: Website | R2: — | S2: =TEXT(M2,"dd-mmmm-yyyy") -> 10-January-2026 | T2: =TEXT(S2,"YYYY") -> 2026 | U2: =TEXT(S2,"MMMM") -> January | V2: =TEXT(S2,"DDDD") -> Saturday
A3: ORD-1002 | C3: ali | D3: =CLEAN(TRIM(C3)) -> ali | E3: =PROPER(TRIM(C3)) -> Ali | F3: Sheikh | G3: LAHORE | H3: Monitor | I3: East | J3: ali8@yahoo.com | K3: =TRIM(IF(J3="","",SUBSTITUTE(SUBSTITUTE(SUBSTITUTE(TRIM(J3),"@@","@"),"..","."),"milto:",""))) -> ali8@yahoo.com | L3: 03001234567 | M3: 05-10-2026 | N3: 3 | O3: 2500 | P3: =SUBSTITUTE(SUBSTITUTE(SUBSTITUTE(O3,"K","000"),"m","000000"),"RS.","") -> 2500 | Q3: Store | S3: =TEXT(M3,"dd-mmmm-yyyy") -> 10-May-2026
A4: ORD-1003 | C4: OMAR | D4: =CLEAN(TRIM(C4)) -> OMAR | E4: =PROPER(TRIM(C4)) -> Omar | F4: Butt | G4: karachi | H4: Laptop | I4: South | J4: omar12@example.com | K4: =TRIM(IF(J4="","",SUBSTITUTE(SUBSTITUTE(SUBSTITUTE(TRIM(J4),"@@","@"),"..","."),"milto:",""))) -> omar12@example.com | L4: 0333-1234567 | M4: 2026-10-01 | N4: 5 | O4: 2500 | P4: =SUBSTITUTE(SUBSTITUTE(SUBSTITUTE(O4,"K","000"),"m","000000"),"RS.","") -> 2500 | Q4: store | S4: =TEXT(M4,"dd-mmmm-yyyy") -> 01-October-2026
A5: ORD-1004 | C5: Fatima | D5: =CLEAN(TRIM(C5)) -> Fatima | E5: =PROPER(TRIM(C5)) -> Fatima | F5: MALIK | G5: Sukkur | H5: USB Drive | I5: SOUTH | J5: fatima72@yahoo.com | K5: =TRIM(IF(J5="","",SUBSTITUTE(SUBSTITUTE(SUBSTITUTE(TRIM(J5),"@@","@"),"..","."),"milto:",""))) -> fatima72@yahoo.com | M5: 2026-10-01 | O5: RS.15K | P5: =SUBSTITUTE(SUBSTITUTE(SUBSTITUTE(O5,"K","000"),"m","000000"),"RS.","") -> 15000 | Q5: Store | R5: N/A | S5: =TEXT(M5,"dd-mmmm-yyyy") -> 01-October-2026
A6: ORD-1005 | C6: Noor | D6: =CLEAN(TRIM(C6)) -> Noor | E6: =PROPER(TRIM(C6)) -> Noor | F6: Butt | G6: Peshawar | H6: Monitor | I6: SOUTH | J6: noor83@gmail.com | K6: =TRIM(IF(J6="","",SUBSTITUTE(SUBSTITUTE(SUBSTITUTE(TRIM(J6),"@@","@"),"..","."),"milto:",""))) -> noor83@gmail.com | L6: 312-5557788 | M6: 2026-10-03 | N6: 5 | O6: 1500 | P6: =SUBSTITUTE(SUBSTITUTE(SUBSTITUTE(O6,"K","000"),"m","000000"),"RS.","") -> 1500 | Q6: WhatsApp | R6: check address | S6: =TEXT(M6,"dd-mmmm-yyyy") -> 03-October-2026
A7: ORD-1006 | C7: OMAR | D7: =CLEAN(TRIM(C7)) -> OMAR | E7: =PROPER(TRIM(C7)) -> Omar | F7: Butt | G7: Hyderabad | H7: Laptop | I7: East | J7: omar48@yahoo.com | K7: =TRIM(IF(J7="","",SUBSTITUTE(SUBSTITUTE(SUBSTITUTE(TRIM(J7),"@@","@"),"..","."),"milto:",""))) -> omar48@yahoo.com | L7: 3001234567 | M7: 2026-10-05 | N7: 3 | O7: 3500 | P7: =SUBSTITUTE(SUBSTITUTE(SUBSTITUTE(O7,"K","000"),"m","000000"),"RS.","") -> 3500 | Q7: Store | R7: N/A | S7: =TEXT(M7,"dd-mmmm-yyyy") -> 2026-10-05
A8: ORD-1007 | C8: ali | D8: =CLEAN(TRIM(C8)) -> ali | E8: =PROPER(TRIM(C8)) -> Ali | F8: QURESHI | G8: Karachi | H8: Mouse | I8: north | J8: ali27@gmail.com | K8: =TRIM(IF(J8="","",SUBSTITUTE(SUBSTITUTE(SUBSTITUTE(TRIM(J8),"@@","@"),"..","."),"milto:",""))) -> ali27@gmail.com | M8: 01/10/2026 | N8: 1 | O8: RS.35000 | P8: =SUBSTITUTE(SUBSTITUTE(SUBSTITUTE(O8,"K","000"),"m","000000"),"RS.","") -> 35000 | Q8: WhatsApp | R8: Urgent | S8: =TEXT(M8,"dd-mmmm-yyyy") -> 10-January-2026
A9: ORD-1008 | C9: SARA | D9: =CLEAN(TRIM(C9)) -> SARA | E9: =PROPER(TRIM(C9)) -> Sara | F9: Siddiqui | G9: Karachi | H9: Monitor | I9: East | J9: sara82@@gmail.com | K9: =TRIM(IF(J9="","",SUBSTITUTE(SUBSTITUTE(SUBSTITUTE(TRIM(J9),"@@","@"),"..","."),"milto:",""))) -> sara82@gmail.com | M9: 2026-10-05 | N9: 3 | O9: RS.35K | P9: =SUBSTITUTE(SUBSTITUTE(SUBSTITUTE(O9,"K","000"),"m","000000"),"RS.","") -> 35000 | Q9: WhatsApp | R9: check address | S9: =TEXT(M9,"dd-mmmm-yyyy") -> 2026-10-05
A10: ORD-1009 | C10: Ayesha | D10: =CLEAN(TRIM(C10)) -> Ayesha | E10: =PROPER(TRIM(C10)) -> Ayesha | F10: Raza | G10: Hyderabad | H10: Monitor | I10: West | J10: ayesha22@example.com23 | K10: =TRIM(IF(J10="","",SUBSTITUTE(SUBSTITUTE(SUBSTITUTE(TRIM(J10),"@@","@"),"..","."),"milto:",""))) -> ayesha22@example.com23 | M10: 2026-10-03 | N10: 4 | O10: 25k | P10: =SUBSTITUTE(SUBSTITUTE(SUBSTITUTE(O10,"K","000"),"m","000000"),"RS.","") -> 25k | Q10: store | R10: Urgent | S10: =TEXT(M10,"dd-mmmm-yyyy") -> 03-October-2026
A11: ORD-1010 | C11: Ayesha | D11: =CLEAN(TRIM(C11)) -> Ayesha | E11: =PROPER(TRIM(C11)) -> Ayesha | F11: Shah | G11: Karachi | H11: Keyboard | I11: East | J11: ayesha2@gmail.com | K11: =TRIM(IF(J11="","",SUBSTITUTE(SUBSTITUTE(SUBSTITUTE(TRIM(J11),"@@","@"),"..","."),"milto:",""))) -> ayesha2@gmail.com | L11: 312-5557788 | M11: 05-10-2026 | N11: 2 | P11: =SUBSTITUTE(SUBSTITUTE(SUBSTITUTE(O11,"K","000"),"m","000000"),"RS.","") | Q11: Store | S11: =TEXT(M11,"dd-mmmm-yyyy") -> 10-May-2026
A12: ORD-1011 | C12: OMAR | D12: =CLEAN(TRIM(C12)) -> OMAR | E12: =PROPER(TRIM(C12)) -> Omar | F12: QURESHI | G12: LAHORE | H12: Laptop | I12: East | J12: omar16@yahoo.com | K12: =TRIM(IF(J12="","",SUBSTITUTE(SUBSTITUTE(SUBSTITUTE(TRIM(J12),"@@","@"),"..","."),"milto:",""))) -> omar16@yahoo.com | M12: 05-10-2026 | N12: 3 | O12: 25000 | P12: =SUBSTITUTE(SUBSTITUTE(SUBSTITUTE(O12,"K","000"),"m","000000"),"RS.","") -> 25000 | Q12: store | R12: N/A | S12: =TEXT(M12,"dd-mmmm-yyyy") -> 10-May-2026
A13: ORD-1012 | C13: Usman | D13: =CLEAN(TRIM(C13)) -> Usman | E13: =PROPER(TRIM(C13)) -> Usman | F13: Raza | G13: Hyderabad | H13: Headphones | I13: West | J13: usman..38@gmail.com | K13: =TRIM(IF(J13="","",SUBSTITUTE(SUBSTITUTE(SUBSTITUTE(TRIM(J13),"@@","@"),"..","."),"milto:",""))) -> usman.38@gmail.com | L13: 0321 444 9988 | M13: 2026-10-03 | N13: 2 | O13: 7500 | P13: =SUBSTITUTE(SUBSTITUTE(SUBSTITUTE(O13,"K","000"),"m","000000"),"RS.","") -> 7500 | Q13: store | R13: — | S13: =TEXT(M13,"dd-mmmm-yyyy") -> 03-October-2026
A14: ORD-1013 | C14: Usman | D14: =CLEAN(TRIM(C14)) -> Usman | F14: Shah | G14: Hyderabad | H14: USB Drive | I14: East | J14: usman89@gmail.com | K14: =TRIM(IF(J14="","",SUBSTITUTE(SUBSTITUTE(SUBSTITUTE(TRIM(J14),"@@","@"),"..","."),"milto:",""))) -> usman89@gmail.com | L14: 0312-5557788 | M14: 05-10-2026 | O14: 15k | P14: =SUBSTITUTE(SUBSTITUTE(SUBSTITUTE(O14,"K","000"),"m","000000"),"RS.","") -> 15k | Q14: Website | R14: check address
A15: ORD-1014 | C15: Fatima | D15: =CLEAN(TRIM(C15)) -> Fatima | F15: MALIK | G15: Islamabad | H15: Mouse | I15: West | J15: fatima73@outlook.com | K15: =TRIM(IF(J15="","",SUBSTITUTE(SUBSTITUTE(SUBSTITUTE(TRIM(J15),"@@","@"),"..","."),"milto:",""))) -> fatima73@outlook.com | L15: 03001234567 | M15: 2026-10-05 | N15: 1 | O15: 12000 | P15: =SUBSTITUTE(SUBSTITUTE(SUBSTITUTE(O15,"K","000"),"m","000000"),"RS.","") -> 12000 | Q15: WhatsApp | R15: N/A
A16: ORD-1015 | C16: Noor | D16: =CLEAN(TRIM(C16)) -> Noor | F16: Ahmed | G16: Multan | H16: Webcam | I16: North | J16: noor48@example.com | K16: =TRIM(IF(J16="","",SUBSTITUTE(SUBSTITUTE(SUBSTITUTE(TRIM(J16),"@@","@"),"..","."),"milto:",""))) -> noor48@example.com | M16: 01/10/2026 | N16: 5 | O16: 3500 | P16: =SUBSTITUTE(SUBSTITUTE(SUBSTITUTE(O16,"K","000"),"m","000000"),"RS.","") -> 3500 | Q16: Website
A17: ORD-1016 | C17: mUHAMMAD | D17: =CLEAN(TRIM(C17)) -> mUHAMMAD | F17: Khan | G17: Karachi | H17: Laptop | I17: West | J17: muhammad49@gmail.com | K17: =TRIM(IF(J17="","",SUBSTITUTE(SUBSTITUTE(SUBSTITUTE(TRIM(J17),"@@","@"),"..","."),"milto:",""))) -> muhammad49@gmail.com | L17: 0321 444 9988 | M17: 01/10/2026 | N17: 2 | Q17: Website | R17: check address
A18: ORD-1017 | C18: hina | D18: =CLEAN(TRIM(C18)) -> hina | F18: QURESHI | G18: Peshawar | H18: USB Drive | I18: SOUTH | J18: hina77@example.com | K18: =TRIM(IF(J18="","",SUBSTITUTE(SUBSTITUTE(SUBSTITUTE(TRIM(J18),"@@","@"),"..","."),"milto:",""))) -> hina77@example.com | M18: 01/10/2026 | N18: 2 | O18: 12000 | Q18: Website
A19: ORD-1012 | C19: Fatima | D19: =CLEAN(TRIM(C19)) -> Fatima | F19: Raza | G19: Sukkur | H19: Laptop | I19: north | J19: fatima12@outlook.com | K19: =TRIM(IF(J19="","",SUBSTITUTE(SUBSTITUTE(SUBSTITUTE(TRIM(J19),"@@","@"),"..","."),"milto:",""))) -> fatima12@outlook.com | L19: 0321 444 9988 | M19: 01/10/2026 | N19: 2 | O19: 250k | Q19: Facebook
A20: ORD-1019 | C20: Fatima | D20: =CLEAN(TRIM(C20)) -> Fatima | F20: Raza | G20: LAHORE | H20: Laptop | I20: North | J20: fatima63@yahoo.com | K20: =TRIM(IF(J20="","",SUBSTITUTE(SUBSTITUTE(SUBSTITUTE(TRIM(J20),"@@","@"),"..","."),"milto:",""))) -> fatima63@yahoo.com | L20: 03001234567 | M20: 05-10-2026 | N20: 5 | O20: 2m | Q20: WhatsApp | R20: check address
A21: ORD-1020 | C21: Usman | D21: =CLEAN(TRIM(C21)) -> Usman | F21: Shah | G21: Sukkur | H21: Laptop | I21: North | J21: usman36@yahoo.com | K21: =TRIM(IF(J21="","",SUBSTITUTE(SUBSTITUTE(SUBSTITUTE(TRIM(J21),"@@","@"),"..","."),"milto:",""))) -> usman36@yahoo.com | L21: 0333-1234567 | M21: 2026-10-03 | N21: 3 | O21: 3500 | Q21: Website | R21: Urgent
A22: ORD-1021 | C22: zain | D22: =CLEAN(TRIM(C22)) -> zain | F22: MALIK | G22: Sukkur | H22: Mouse | I22: SOUTH | J22: zain65@yahoo.com | K22: =TRIM(IF(J22="","",SUBSTITUTE(SUBSTITUTE(SUBSTITUTE(TRIM(J22),"@@","@"),"..","."),"milto:",""))) -> zain65@yahoo.com | L22: 0333-1234567 | M22: 2026-10-05 | N22: 4 | O22: 12000 | Q22: WhatsApp
A23: ORD-1022 | C23: Ayesha | D23: =CLEAN(TRIM(C23)) -> Ayesha | F23: Butt | G23: Multan | H23: USB Drive | I23: north | J23: ayesha14@outlook.com | K23: =TRIM(IF(J23="","",SUBSTITUTE(SUBSTITUTE(SUBSTITUTE(TRIM(J23),"@@","@"),"..","."),"milto:",""))) -> ayesha14@outlook.com | L23: 0321 444 9988 | M23: 2026-10-01 | O23: 1500 | Q23: WhatsApp | R23: check address
A24: ORD-1023 | C24: Usman | D24: =CLEAN(TRIM(C24)) -> Usman | F24: Raza | G24: Hyderabad | H24: Mouse | I24: North | J24: usman70@yahoo.com | K24: =TRIM(IF(J24="","",SUBSTITUTE(SUBSTITUTE(SUBSTITUTE(TRIM(J24),"@@","@"),"..","."),"milto:",""))) -> usman70@yahoo.com | L24: 0321 444 9988 | M24: 2026-10-05 | N24: 2 | Q24: WhatsApp
A25: ORD-1024 | C25: Fatima | D25: =CLEAN(TRIM(C25)) -> Fatima | F25: Raza | G25: Hyderabad | H25: Monitor | I25: north | J25: fatima78@outlook.com | K25: =TRIM(IF(J25="","",SUBSTITUTE(SUBSTITUTE(SUBSTITUTE(TRIM(J25),"@@","@"),"..","."),"milto:",""))) -> fatima78@outlook.com | L25: 0312-5557788 | M25: 01/10/2026 | N25: 3 | O25: 7500 | Q25: Website | R25: check address
A26: ORD-1025 | C26: ali | D26: =CLEAN(TRIM(C26)) -> ali | F26: Sheikh | G26: Multan | H26: Monitor | I26: West | J26: sara82@gmail.com | K26: =TRIM(IF(J26="","",SUBSTITUTE(SUBSTITUTE(SUBSTITUTE(TRIM(J26),"@@","@"),"..","."),"milto:",""))) -> sara82@gmail.com | L26: 0333-1234567 | M26: 2026-10-05 | O26: 3500 | Q26: Website | R26: N/A
A27: ORD-1026 | C27: Fatima | D27: =CLEAN(TRIM(C27)) -> Fatima | F27: MALIK | G27: LAHORE | H27: Webcam | I27: North | J27: fatima67@gmail.com | K27: =TRIM(IF(J27="","",SUBSTITUTE(SUBSTITUTE(SUBSTITUTE(TRIM(J27),"@@","@"),"..","."),"milto:",""))) -> fatima67@gmail.com | L27: 0321 444 9988 | M27: 2026-10-03 | N27: 1 | O27: 3500 | Q27: Facebook | R27: Urgent
A28: ORD-1027 | C28: hina | D28: =CLEAN(TRIM(C28)) -> hina | F28: Shah | G28: Karachi | H28: USB Drive | I28: East | J28: hina22@yahoo.com | K28: =TRIM(IF(J28="","",SUBSTITUTE(SUBSTITUTE(SUBSTITUTE(TRIM(J28),"@@","@"),"..","."),"milto:",""))) -> hina22@yahoo.com | L28: 0312-5557788 | M28: 01/10/2026 | N28: 1 | Q28: Website
A29: ORD-1028 | C29: hina | D29: =CLEAN(TRIM(C29)) -> hina | F29: Shah | G29: LAHORE | H29: Webcam | I29: East | J29: hina14@outlook.com | K29: =TRIM(IF(J29="","",SUBSTITUTE(SUBSTITUTE(SUBSTITUTE(TRIM(J29),"@@","@"),"..","."),"milto:",""))) -> hina14@outlook.com | L29: 0333-1234567 | M29: 05-10-2026 | N29: 1 | O29: 12000 | Q29: Website | R29: Urgent
A30: ORD-1029 | C30: Usman | D30: =CLEAN(TRIM(C30)) -> Usman | F30: Ahmed | G30: Karachi | H30: Headphones | I30: North | J30: usman82@outlook.com | K30: =TRIM(IF(J30="","",SUBSTITUTE(SUBSTITUTE(SUBSTITUTE(TRIM(J30),"@@","@"),"..","."),"milto:",""))) -> usman82@outlook.com | L30: 0333-1234567 | M30: 2026-10-03 | N30: 5 | O30: 7500 | Q30: WhatsApp
A31: ORD-1030 | C31: Fatima | D31: =CLEAN(TRIM(C31)) -> Fatima | F31: Butt | G31: Karachi | H31: Headphones | I31: East | J31: fatima97@outlook.com | K31: =TRIM(IF(J31="","",SUBSTITUTE(SUBSTITUTE(SUBSTITUTE(TRIM(J31),"@@","@"),"..","."),"milto:",""))) -> fatima97@outlook.com | L31: 03001234567 | M31: 2026-10-05 | N31: 2 | O31: 7500 | Q31: Website | R31: —
A32: ORD-1031 | C32: Fatima | D32: =CLEAN(TRIM(C32)) -> Fatima | F32: Sheikh | G32: Sukkur | H32: Webcam | I32: South | J32: fatima30@gmail.com | K32: =TRIM(IF(J32="","",SUBSTITUTE(SUBSTITUTE(SUBSTITUTE(TRIM(J32),"@@","@"),"..","."),"milto:",""))) -> fatima30@gmail.com | L32: 0333-1234567 | M32: 2026-10-01 | N32: 3 | O32: 1500 | Q32: Store
A33: ORD-1032 | C33: ali | D33: =CLEAN(TRIM(C33)) -> ali | F33: Shah | G33: Karachi | H33: Laptop | I33: north | J33: ali93@gmail.com | K33: =TRIM(IF(J33="","",SUBSTITUTE(SUBSTITUTE(SUBSTITUTE(TRIM(J33),"@@","@"),"..","."),"milto:",""))) -> ali93@gmail.com | M33: 01/10/2026 | N33: 5 | O33: 12000 | Q33: store | R33: —
A34: ORD-1033 | C34: Usman | D34: =CLEAN(TRIM(C34)) -> Usman | F34: Shah | G34: Peshawar | H34: Webcam | I34: East | J34: usman41@yahoo.com | K34: =TRIM(IF(J34="","",SUBSTITUTE(SUBSTITUTE(SUBSTITUTE(TRIM(J34),"@@","@"),"..","."),"milto:",""))) -> usman41@yahoo.com | L34: 0333-1234567 | M34: 2026-10-01 | O34: 12000 | Q34: WhatsApp
A35: ORD-1034 | C35: Noor | D35: =CLEAN(TRIM(C35)) -> Noor | F35: Raza | G35: Karachi | H35: Webcam | I35: north | J35: noor16@example.com | K35: =TRIM(IF(J35="","",SUBSTITUTE(SUBSTITUTE(SUBSTITUTE(TRIM(J35),"@@","@"),"..","."),"milto:",""))) -> noor16@example.com | M35: 01/10/2026 | N35: 2 | O35: 3500 | Q35: Facebook
A36: ORD-1035 | C36: hina | D36: =CLEAN(TRIM(C36)) -> hina | F36: Khan | G36: Islamabad | H36: Mouse | I36: South | J36: hina44@example.com | K36: =TRIM(IF(J36="","",SUBSTITUTE(SUBSTITUTE(SUBSTITUTE(TRIM(J36),"@@","@"),"..","."),"milto:",""))) -> hina44@example.com | L36: 0321 444 9988 | M36: 2026-10-03 | N36: 4 | O36: 25000 | Q36: WhatsApp | R36: —
A37: ORD-1036 | C37: Fatima | D37: =CLEAN(TRIM(C37)) -> Fatima | F37: Iqbal | G37: Sukkur | H37: Mouse | I37: SOUTH | J37: fatima47@gmail.com | K37: =TRIM(IF(J37="","",SUBSTITUTE(SUBSTITUTE(SUBSTITUTE(TRIM(J37),"@@","@"),"..","."),"milto:",""))) -> fatima47@gmail.com | L37: 0312-5557788 | M37: 2026-10-03 | N37: 5 | O37: 12000 | Q37: store | R37: N/A
A38: ORD-1012 | C38: hina | D38: =CLEAN(TRIM(C38)) -> hina | F38: Sheikh | G38: LAHORE | H38: Webcam | I38: SOUTH | J38: hina36@outlook.com | K38: =TRIM(IF(J38="","",SUBSTITUTE(SUBSTITUTE(SUBSTITUTE(TRIM(J38),"@@","@"),"..","."),"milto:",""))) -> hina36@outlook.com | L38: 0321 444 9988 | M38: 2026-10-05 | N38: 4 | O38: 25000 | Q38: store
A39: ORD-1038 | C39: SARA | D39: =CLEAN(TRIM(C39)) -> SARA | F39: Sheikh | G39: Peshawar | H39: Mouse | I39: East | J39: sara80@outlook.com | K39: =TRIM(IF(J39="","",SUBSTITUTE(SUBSTITUTE(SUBSTITUTE(TRIM(J39),"@@","@"),"..","."),"milto:",""))) -> sara80@outlook.com | L39: 0333-1234567 | M39: 2026-10-03 | N39: 2 | O39: 12000 | Q39: Website | R39: check address
A40: ORD-1039 | C40: OMAR | D40: =CLEAN(TRIM(C40)) -> OMAR | F40: Raza | G40: Sukkur | H40: USB Drive | I40: SOUTH | J40: omar80@example.com | K40: =TRIM(IF(J40="","",SUBSTITUTE(SUBSTITUTE(SUBSTITUTE(TRIM(J40),"@@","@"),"..","."),"milto:",""))) -> omar80@example.com | L40: 0312-5557788 | M40: 2026-10-03 | N40: 1 | O40: 2500 | Q40: WhatsApp | R40: —
...

Sheet product
A1: Product ID | B1: Product Name | C1: Category
A2: PD-100 | B2: Keyboard | C2: Input Device
A3: PD-101 | B3: Mouse | C3: Input Device
A4: PD-102 | B4: Hard Drive | C4: Storage
A5: PD-103 | B5: USB Flash Drive | C5: Storage
A6: PD-104 | B6: Monitor | C6: Display
A7: PD-105 | B7: Graphics Card | C7: Internal Hardware
A8: PD-106 | B8: RAM Module | C8: Internal Hardware
A9: PD-107 | B9: SSD | C9: Internal Hardware
A10: PD-108 | B10: HDMI Cable | C10: Cables & Connectors
A11: PD-109 | B11: Webcam | C11: Peripherals
A12: PD-110 | B12: Laptop Stand | C12: Laptop Accessories
... A20: PD-118 | B20: Laptop Bag | C20: Laptop Accessories

Sheet Sale Sheet
A1: Order ID | B1: Product ID | C1: Product | D1: Category | E1: Quantity Sold | F1: Rate | G1: Sales | H1: Date | I1: State | J1: Ship Mode | K1: Segment | L1: Seller_ID | N1: Groupby
A2: 1743 | B2: PD-110 | C2: =_xlfn.XLOOKUP(B2,product!$A$2:$A$20,product!$B$2:$B$20) -> Laptop Stand | D2: =_xlfn.XLOOKUP(C2,product!$B$2:$B$20,product!$C$2:$C$20) -> Laptop Accessories | E2: 175 | F2: 500 | G2: 87500 | H2: 44562 | I2: Faisalabad | J2: First Class | K2: Home Office | L2: COM3737 | N2: {=_xlfn.GROUPBY(C1:C366,G1:G366,_xleta.SUM,3)} -> Product | O2: Sales
A3: 1447 | B3: PD-107 | C3: =_xlfn.XLOOKUP(B3,product!$A$2:$A$20,product!$B$2:$B$20) -> SSD | D3: =_xlfn.XLOOKUP(C3,product!$B$2:$B$20,product!$C$2:$C$20) -> Internal Hardware | E3: 293 | F3: 9500 | G3: 2783500 | H3: 44563 | I3: Rawalpindi | J3: Standard Class | K3: Consumer | L3: COM6175 | N3: Cooling Pad | O3: 9118062
A4: 1802 | B4: PD-116 | C4: =_xlfn.XLOOKUP(B4,product!$A$2:$A$20,product!$B$2:$B$20) -> Wireless Router | D4: =_xlfn.XLOOKUP(C4,product!$B$2:$B$20,product!$C$2:$C$20) -> Network | E4: 177 | F4: 1350 | G4: 238950 | H4: 44564 | I4: Multan | J4: Second Class | K4: Home Office | L4: COM8842 | N4: Ethernet Cable | O4: 11552316
A5: 1495 | B5: PD-104 | C5: =_xlfn.XLOOKUP(B5,product!$A$2:$A$20,product!$B$2:$B$20) -> Monitor | D5: =_xlfn.XLOOKUP(C5,product!$B$2:$B$20,product!$C$2:$C$20) -> Display | E5: 192 | F5: 1350 | G5: 259200 | H5: 44565 | I5: Gujranwala | J5: First Class | K5: Consumer | L5: COM2184 | N5: Graphics Card | O5: 23145017
A6: 1570 | B6: PD-110 | C6: =_xlfn.XLOOKUP(B6,product!$A$2:$A$20,product!$B$2:$B$20) -> Laptop Stand | D6: =_xlfn.XLOOKUP(C6,product!$B$2:$B$20,product!$C$2:$C$20) -> Laptop Accessories | E6: 148 | F6: 500 | G6: 74000 | H6: 44566 | I6: Sialkot | J6: First Class | K6: Home Office | L6: COM3726 | N6: Hard Drive | O6: 11088474
A7: 1822 | B7: PD-105 | C7: =_xlfn.XLOOKUP(B7,product!$A$2:$A$20,product!$B$2:$B$20) -> Graphics Card | D7: =_xlfn.XLOOKUP(C7,product!$B$2:$B$20,product!$C$2:$C$20) -> Internal Hardware | E7: 262 | F7: 12000 | G7: 3144000 | H7: 44567 | I7: Bahawalpur | J7: Standard Class | K7: Corporate | L7: COM3175 | N7: HDMI Cable | O7: 10452262
A8: 1699 | B8: PD-100 | C8: =_xlfn.XLOOKUP(B8,product!$A$2:$A$20,product!$B$2:$B$20) -> Keyboard | D8: =_xlfn.XLOOKUP(C8,product!$B$2:$B$20,product!$C$2:$C$20) -> Input Device | E8: 259 | F8: 800 | G8: 207200 | H8: 44568 | I8: Sargodha | J8: First Class | K8: Consumer | L8: COM7392 | N8: Headset | O8: 23648174
A9: 1492 | B9: PD-104 | C9: =_xlfn.XLOOKUP(B9,product!$A$2:$A$20,product!$B$2:$B$20) -> Monitor | D9: =_xlfn.XLOOKUP(C9,product!$B$2:$B$20,product!$C$2:$C$20) -> Display | E9: 232 | F9: 15000 | G9: 3480000 | H9: 44569 | I9: Karachi | J9: Standard Class | K9: Home Office | L9: COM3575 | N9: Keyboard | O9: 7929345
A10: 1670 | B10: PD-101 | C10: =_xlfn.XLOOKUP(B10,product!$A$2:$A$20,product!$B$2:$B$20) -> Mouse | D10: =_xlfn.XLOOKUP(C10,product!$B$2:$B$20,product!$C$2:$C$20) -> Input Device | E10: 153 | F10: 500 | G10: 76500 | H10: 44570 | I10: Hyderabad | J10: First Class | K10: Corporate | L10: COM7966 | N10: Laptop Bag | O10: 4333076
A11: 1244 | B11: PD-112 | C11: =_xlfn.XLOOKUP(B11,product!$A$2:$A$20,product!$B$2:$B$20) -> Headset | D11: =_xlfn.XLOOKUP(C11,product!$B$2:$B$20,product!$C$2:$C$20) -> Audio | E11: 192 | F11: 1500 | G11: 288000 | H11: 44571 | I11: Sukkur | J11: First Class | K11: Consumer | L11: COM1490 | N11: Laptop Stand | O11: 8175881
A12: 1502 | B12: PD-102 | C12: =_xlfn.XLOOKUP(B12,product!$A$2:$A$20,product!$B$2:$B$20) -> Hard Drive | D12: =_xlfn.XLOOKUP(C12,product!$B$2:$B$20,product!$C$2:$C$20) -> Storage | E12: 116 | F12: 8000 | G12: 928000 | H12: 44572 | I12: Larkana | J12: Standard Class | K12: Corporate | L12: COM5769 | N12: Monitor | O12: 33857315
A13: 1493 | B13: PD-104 | C13: =_xlfn.XLOOKUP(B13,product!$A$2:$A$20,product!$B$2:$B$20) -> Monitor | D13: =_xlfn.XLOOKUP(C13,product!$B$2:$B$20,product!$C$2:$C$20) -> Display | E13: 153 | F13: 15000 | G13: 2295000 | H13: 44573 | I13: Nawabshah | J13: Second Class | K13: Home Office | L13: COM8095 | N13: Mouse | O13: 8503053
A14: 1987 | B14: PD-115 | C14: =_xlfn.XLOOKUP(B14,product!$A$2:$A$20,product!$B$2:$B$20) -> Speakers | D14: =_xlfn.XLOOKUP(C14,product!$B$2:$B$20,product!$C$2:$C$20) -> Audio | E14: 279 | F14: 5300 | G14: 1478700 | H14: 44574 | I14: Mirpur Khas | J14: First Class | K14: Corporate | L14: COM1606 | N14: Printer | O14: 22183044
... A22: 1394 | B22: PD-118 | C22: =_xlfn.XLOOKUP(B22,product!$A$2:$A$20,product!$B$2:$B$20) -> Laptop Bag | D22: =_xlfn.XLOOKUP(C22,product!$B$2:$B$20,product!$C$2:$C$20) -> Laptop Accessories | E22: 110 | F22: 300 | G22: 33000 | H22: 44582 | I22: Karachi | J22: Standard Class | K22: Corporate | L22: COM3175 | N22: Total | O22: 275802158
A23: 1049 | B23: PD-111 | C23: =_xlfn.XLOOKUP(B23,product!$A$2:$A$20,product!$B$2:$B$20) -> Cooling Pad | D23: =_xlfn.XLOOKUP(C23,product!$B$2:$B$20,product!$C$2:$C$20) -> Laptop Accessories | E23: 254 | F23: 650 | G23: 165100 | H23: 44583 | I23: Sukkur | J23: Second Class | K23: Consumer | L23: COM7392
A24: 1005 | B24: PD-109 | C24: =_xlfn.XLOOKUP(B24,product!$A$2:$A$20,product!$B$2:$B$20) -> Webcam | D24: =_xlfn.XLOOKUP(C24,product!$B$2:$B$20,product!$C$2:$C$20) -> Peripherals | E24: 203 | F24: 3500 | G24: 710500 | H24: 44584 | I24: Larkana | J24: First Class | K24: Consumer | L24: COM3575
A25: 1831 | B25: PD-115 | C25: =_xlfn.XLOOKUP(B25,product!$A$2:$A$20,product!$B$2:$B$20) -> Speakers | D25: =_xlfn.XLOOKUP(C25,product!$B$2:$B$20,product!$C$2:$C$20) -> Audio | E25: 183 | F25: 5300 | G25: 969900 | H25: 44585 | I25: Nawabshah | J25: Second Class | K25: Consumer | L25: COM7966 | N25: Filter
A26: 1530 | B26: PD-112 | C26: =_xlfn.XLOOKUP(B26,product!$A$2:$A$20,product!$B$2:$B$20) -> Headset | D26: =_xlfn.XLOOKUP(C26,product!$B$2:$B$20,product!$C$2:$C$20) -> Audio | E26: 184 | F26: 1500 | G26: 276000 | H26: 44586 | I26: Mirpur Khas | J26: First Class | K26: Home Office | L26: COM1490 | N26: {=_xlfn._xlws.FILTER(A1:L366,(I1:I366="Multan")*(L1:L366="COM3737"))} -> 1956 | O26: PD-105 | P26: Graphics Card | Q26: Internal Hardware | R26: 180 | S26: 12000 | T26: 2160000 | U26: 44577 | V26: Multan | W26: First Class | X26: Home Office | Y26: COM3737
A27: 1123 | B27: PD-106 | C27: =_xlfn.XLOOKUP(B27,product!$A$2:$A$20,product!$B$2:$B$20) -> RAM Module | D27: =_xlfn.XLOOKUP(C27,product!$B$2:$B$20,product!$C$2:$C$20) -> Internal Hardware | E27: 280 | F27: 7500 | G27: 2100000 | H27: 44587 | I27: Faisalabad | J27: First Class | K27: Home Office | L27: COM5769 | N27: 288 | O27: PD-113 | P27: Printer | Q27: Peripherals | R27: 200 | S27: 2009 | T27: 401800 | U27: 44697 | V27: Multan | W27: Second Class | X27: Corporate | Y27: COM3737
A28: 1227 | B28: PD-107 | C28: =_xlfn.XLOOKUP(B28,product!$A$2:$A$20,product!$B$2:$B$20) -> SSD | D28: =_xlfn.XLOOKUP(C28,product!$B$2:$B$20,product!$C$2:$C$20) -> Internal Hardware | E28: 210 | F28: 9500 | G28: 1995000 | H28: 44588 | I28: Rawalpindi | J28: First Class | K28: Corporate | L28: COM8095 | N28: 288 | O28: PD-102 | P28: Hard Drive | Q28: Storage | R28: 247 | S28: 2729 | T28: 674063 | U28: 44817 | V28: Multan | W28: First Class | X28: Corporate | Y28: COM3737
A29: 1627 | B29: PD-117 | C29: =_xlfn.XLOOKUP(B29,product!$A$2:$A$20,product!$B$2:$B$20) -> Ethernet Cable | D29: =_xlfn.XLOOKUP(C29,product!$B$2:$B$20,product!$C$2:$C$20) -> Cables & Connectors | E29: 289 | F29: 600 | G29: 173400 | H29: 44589 | I29: Multan | J29: Second Class | K29: Home Office | L29: COM1606
A30: 1112 | B30: PD-112 | C30: =_xlfn.XLOOKUP(B30,product!$A$2:$A$20,product!$B$2:$B$20) -> Headset | D30: =_xlfn.XLOOKUP(C30,product!$B$2:$B$20,product!$C$2:$C$20) -> Audio | E30: 260 | F30: 1500 | G30: 390000 | H30: 44590 | I30: Gujranwala | J30: First Class | K30: Consumer | L30: COM7245
A31: 1966 | B31: PD-113 | C31: =_xlfn.XLOOKUP(B31,product!$A$2:$A$20,product!$B$2:$B$20) -> Printer | D31: =_xlfn.XLOOKUP(C31,product!$B$2:$B$20,product!$C$2:$C$20) -> Peripherals | E31: 186 | F31: 11500 | G31: 2139000 | H31: 44591 | I31: Sialkot | J31: Standard Class | K31: Home Office | L31: COM8968
A32: 1600 | B32: PD-117 | C32: =_xlfn.XLOOKUP(B32,product!$A$2:$A$20,product!$B$2:$B$20) -> Ethernet Cable | D32: =_xlfn.XLOOKUP(C32,product!$B$2:$B$20,product!$C$2:$C$20) -> Cables & Connectors | E32: 187 | F32: 600 | G32: 112200 | H32: 44592 | I32: Bahawalpur | J32: Second Class | K32: Corporate | L32: COM3737
A33: 1919 | B33: PD-108 | C33: =_xlfn.XLOOKUP(B33,product!$A$2:$A$20,product!$B$2:$B$20) -> HDMI Cable | D33: =_xlfn.XLOOKUP(C33,product!$B$2:$B$20,product!$C$2:$C$20) -> Cables & Connectors | E33: 149 | F33: 250 | G33: 37250 | H33: 44593 | I33: Sargodha | J33: Second Class | K33: Consumer | L33: COM6175 | N33: {=_xlfn.PIVOTBY(C1:C366,D1:D366,G1:G366,_xleta.SUM,3,1,1,1,1,K1:K366="Consumer",2)} | O33: Category
A34: 1170 | B34: PD-102 | C34: =_xlfn.XLOOKUP(B34,product!$A$2:$A$20,product!$B$2:$B$20) -> Hard Drive | D34: =_xlfn.XLOOKUP(C34,product!$B$2:$B$20,product!$C$2:$C$20) -> Storage | E34: 253 | F34: 8000 | G34: 2024000 | H34: 44594 | I34: Karachi | J34: Standard Class | K34: Corporate | L34: COM8842 | O34: Audio | P34: Cables & Connectors | Q34: Display | R34: Input Device | S34: Internal Hardware | T34: Laptop Accessories | U34: Network | V34: Peripherals | W34: Total
A35: 1366 | B35: PD-104 | C35: =_xlfn.XLOOKUP(B35,product!$A$2:$A$20,product!$B$2:$B$20) -> Monitor | D35: =_xlfn.XLOOKUP(C35,product!$B$2:$B$20,product!$C$2:$C$20) -> Display | E35: 222 | F35: 15000 | G35: 3330000 | H35: 44595 | I35: Sialkot | J35: First Class | K35: Consumer | L35: COM2184 | N35: Product | O35: Sales | P35: Sales | Q35: Sales | R35: Sales | S35: Sales | T35: Sales | U35: Sales | V35: Sales | W35: Sales
A36: 1307 | B36: PD-106 | C36: =_xlfn.XLOOKUP(B36,product!$A$2:$A$20,product!$B$2:$B$20) -> RAM Module | D36: =_xlfn.XLOOKUP(C36,product!$B$2:$B$20,product!$C$2:$C$20) -> Internal Hardware | E36: 242 | F36: 7500 | G36: 1815000 | H36: 44596 | I36: Bahawalpur | J36: Second Class | K36: Consumer | L36: COM3726 | N36: Cooling Pad | T36: 1215152 | W36: 1215152
A37: 1820 | B37: PD-113 | C37: =_xlfn.XLOOKUP(B37,product!$A$2:$A$20,product!$B$2:$B$20) -> Printer | D37: =_xlfn.XLOOKUP(C37,product!$B$2:$B$20,product!$C$2:$C$20) -> Peripherals | E37: 184 | F37: 11500 | G37: 2116000 | H37: 44597 | I37: Sargodha | J37: Second Class | K37: Corporate | L37: COM3175 | N37: Ethernet Cable | P37: 1853598 | W37: 1853598
A38: 1835 | B38: PD-106 | C38: =_xlfn.XLOOKUP(B38,product!$A$2:$A$20,product!$B$2:$B$20) -> RAM Module | D38: =_xlfn.XLOOKUP(C38,product!$B$2:$B$20,product!$C$2:$C$20) -> Internal Hardware | E38: 276 | F38: 7500 | G38: 2070000 | H38: 44598 | I38: Karachi | J38: First Class | K38: Corporate | L38: COM7392 | N38: HDMI Cable | P38: 5010357 | W38: 5010357
A39: 1866 | B39: PD-111 | C39: =_xlfn.XLOOKUP(B39,product!$A$2:$A$20,product!$B$2:$B$20) -> Cooling Pad | D39: =_xlfn.XLOOKUP(C39,product!$B$2:$B$20,product!$C$2:$C$20) -> Laptop Accessories | E39: 225 | F39: 650 | G39: 146250 | H39: 44599 | I39: Hyderabad | J39: First Class | K39: Home Office | L39: COM3575 | N39: Headset | O39: 13461945 | W39: 13461945
A40: 1900 | B40: PD-103 | C40: =_xlfn.XLOOKUP(B40,product!$A$2:$A$20,product!$B$2:$B$20) -> USB Flash Drive | D40: =_xlfn.XLOOKUP(C40,product!$B$2:$B$20,product!$C$2:$C$20) -> Storage | E40: 255 | F40: 600 | G40: 153000 | H40: 44600 | I40: Sukkur | J40: First Class | K40: Corporate | L40: COM7966 | N40: Keyboard | R40: 5029071 | W40: 5029071
A41: 1968 | B41: PD-114 | C41: =_xlfn.XLOOKUP(B41,product!$A$2:$A$20,product!$B$2:$B$20) -> Scanner | D41: =_xlfn.XLOOKUP(C41,product!$B$2:$B$20,product!$C$2:$C$20) -> Peripherals | E41: 298 | F41: 7600 | G41: 2264800 | H41: 44601 | I41: Larkana | J41: Second Class | K41: Home Office | L41: COM1490 | N41: Laptop Bag | T41: 1787264 | W41: 1787264
A42: 1302 | B42: PD-117 | C42: =_xlfn.XLOOKUP(B42,product!$A$2:$A$20,product!$B$2:$B$20) -> Ethernet Cable | D42: =_xlfn.XLOOKUP(C42,product!$B$2:$B$20,product!$C$2:$C$20) -> Cables & Connectors | E42: 212 | F42: 600 | G42: 127200 | H42: 44602 | I42: Nawabshah | J42: First Class | K42: Consumer | L42: COM5769 | N42: Laptop Stand | T42: 1782373 | W42: 1782373
A43: 1246 | B43: PD-109 | C43: =_xlfn.XLOOKUP(B43,product!$A$2:$A$20,product!$B$2:$B$20) -> Webcam | D43: =_xlfn.XLOOKUP(C43,product!$B$2:$B$20,product!$C$2:$C$20) -> Peripherals | E43: 107 | F43: 3500 | G43: 374500 | H43: 44603 | I43: Mirpur Khas | J43: Second Class | K43: Corporate | L43: COM8095 | N43: Monitor | Q43: 19396419 | W43: 19396419
A44: 1788 | B44: PD-103 | C44: =_xlfn.XLOOKUP(B44,product!$A$2:$A$20,product!$B$2:$B$20) -> USB Flash Drive | D44: =_xlfn.XLOOKUP(C44,product!$B$2:$B$20,product!$C$2:$C$20) -> Storage | E44: 162 | F44: 600 | G44: 97200 | H44: 44604 | I44: Faisalabad | J44: Standard Class | K44: Corporate | L44: COM1606 | N44: Mouse | R44: 3370704 | W44: 3370704
A45: 1999 | B45: PD-110 | C45: =_xlfn.XLOOKUP(B45,product!$A$2:$A$20,product!$B$2:$B$20) -> Laptop Stand | D45: =_xlfn.XLOOKUP(C45,product!$B$2:$B$20,product!$C$2:$C$20) -> Laptop Accessories | E45: 234 | F45: 500 | G45: 117000 | H45: 44605 | I45: Rawalpindi | J45: First Class | K45: Consumer | L45: COM7245 | N45: RAM Module | S45: 7238722 | W45: 7238722
A46: 1889 | B46: PD-104 | C46: =_xlfn.XLOOKUP(B46,product!$A$2:$A$20,product!$B$2:$B$20) -> Monitor | D46: =_xlfn.XLOOKUP(C46,product!$B$2:$B$20,product!$C$2:$C$20) -> Display | E46: 166 | F46: 15000 | G46: 2490000 | H46: 44606 | I46: Multan | J46: Standard Class | K46: Consumer | L46: COM8968 | N46: Speakers | O46: 5589941 | W46: 5589941
A47: 1525 | B47: PD-106 | C47: =_xlfn.XLOOKUP(B47,product!$A$2:$A$20,product!$B$2:$B$20) -> RAM Module | D47: =_xlfn.XLOOKUP(C47,product!$B$2:$B$20,product!$C$2:$C$20) -> Internal Hardware | E47: 277 | F47: 7500 | G47: 2077500 | H47: 44607 | I47: Gujranwala | J47: Second Class | K47: Corporate | L47: COM3737 | N47: SSD | S47: 5009112 | W47: 5009112
...

Sheet prediction 
A1: Month | B1: Month_Number | C1: Actual_Sales | D1: Orders
A2: 45292 | B2: 1 | C2: 42000 | D2: 12 | G2: Task | H2: Formula
A3: 45323 | B3: 2 | C3: 44500 | D3: 15 | G3: Predict Month 31 sales | H3: =_xlfn.FORECAST.LINEAR(31,C2:C31,B2:B31) -> 96709.195
A4: 45352 | B4: 3 | C4: 47000 | D4: 18 | G4: Predict Month 32 sales | H4: =_xlfn.FORECAST.LINEAR(32,C2:C31,B2:B31) -> 98549.574
A5: 45383 | B5: 4 | C5: 45500 | D5: 14 | G5: Calculate monthly trend | H5: =SLOPE(C2:C31,B2:B31) -> 1840.3782
A6: 45413 | B6: 5 | C6: 49000 | D6: 20 | G6: Calculate trend intercept | H6: =INTERCEPT(C2:C31,B2:B31) -> 39657.471
A7: 45444 | B7: 6 | C7: 51500 | D7: 22
A8: 45474 | B8: 7 | C8: 53000 | D8: 19 | G8: Calculate average sales | H8: =AVERAGE(C2:C31) -> 68183.333
A9: 45505 | B9: 8 | C9: 52000 | D9: 21 | G9: Find maximum sales | H9: =MAX(C2:C31) -> 96000
A10: 45536 | B10: 9 | C10: 56000 | D10: 24 | G10: Find minimum sales | H10: =MIN(C2:C31) -> 42000
A11: 45566 | B11: 10 | C11: 58500 | D11: 25 | G11: Forecast Months 31–33 | H11: {=TREND(C2:C31,B2:B31,{31;32;33;34})} -> 96709.195
A12: 45597 | B12: 11 | C12: 60000 | D12: 28 | H12: 98549.574
A13: 45627 | B13: 12 | C13: 62500 | D13: 30 | H13: 100389.95
A14: 45658 | B14: 13 | C14: 61000 | D14: 26 | H14: 102230.33
A15: 45689 | B15: 14 | C15: 65000 | D15: 29
A16: 45717 | B16: 15 | C16: 67500 | D16: 31
A17: 45748 | B17: 16 | C17: 69000 | D17: 33
A18: 45778 | B18: 17 | C18: 71500 | D18: 32
A19: 45809 | B19: 18 | C19: 70000 | D19: 30
A20: 45839 | B20: 19 | C20: 74500 | D20: 34
A21: 45870 | B21: 20 | C21: 77000 | D21: 35
A22: 45901 | B22: 21 | C22: 79000 | D22: 37
A23: 45931 | B23: 22 | C23: 80500 | D23: 36
A24: 45962 | B24: 23 | C24: 83000 | D24: 39
A25: 45992 | B25: 24 | C25: 82000 | D25: 38
A26: 46023 | B26: 25 | C26: 86000 | D26: 41
... A31: 46174 | B31: 30 | C31: 96000 | D31: 48

Sheet text formulas 
A1: First_Name | B1: Last_Name | C1: Gender | D1: Department | E1: Joining_Date | F1: Salary | G1: Employee_ID | H1: Full Name | I1: Full Name | J1: text before | K1: text after | N1: TextSlit
A2: Ali | B2: Khan | C2: Male | D2: Sales | E2: 45306 | F2: 45000 | G2: EMP-1001 | H2: =_xlfn.TEXTJOIN(" ",TRUE,A2,B2) -> Ali Khan | I2: =IF(C2="Male",_xlfn.TEXTJOIN(" S/o ",TRUE,A2,B2),_xlfn.TEXTJOIN(" W/o ",TRUE,A2,B2)) -> Ali S/o Khan | J2: =_xlfn.TEXTBEFORE(G2,"-") -> EMP | K2: =_xlfn.TEXTAFTER(G2,"-") -> 1001 | M2: Ali-Ahmed-XII | N2: {=_xlfn.TEXTSPLIT(M2,"-")} -> Ali | O2: Ahmed | P2: XII
A3: Sara | B3: Ahmed | C3: Female | D3: HR | E3: 45066 | F3: 52000 | G3: EMP-1002 | H3: =_xlfn.TEXTJOIN(" ",TRUE,A3,B3) -> Sara Ahmed | I3: =IF(C3="Male",_xlfn.TEXTJOIN(" S/o ",TRUE,A3,B3),_xlfn.TEXTJOIN(" W/o ",TRUE,A3,B3)) -> Sara W/o Ahmed | J3: =_xlfn.TEXTBEFORE(G3,"-") -> EMP | K3: =_xlfn.TEXTAFTER(G3,"-") -> 1002 | M3: Sara-Ahmed-Female-HR | N3: {=_xlfn.TEXTSPLIT(M3,"-")} -> Sara | O3: Ahmed | P3: Female | Q3: HR
A4: Muhammad | B4: Malik | C4: Male | D4: IT | E4: 44783 | F4: 75000 | G4: EMP-1003 | H4: =_xlfn.TEXTJOIN(" ",TRUE,A4,B4) -> Muhammad Malik | I4: =IF(C4="Male",_xlfn.TEXTJOIN(" S/o ",TRUE,A4,B4),_xlfn.TEXTJOIN(" W/o ",TRUE,A4,B4)) -> Muhammad S/o Malik | J4: =_xlfn.TEXTBEFORE(G4,"-") -> EMP | K4: =_xlfn.TEXTAFTER(G4,"-") -> 1003 | M4: Muhammad-Malik-Male-IT | N4: {=_xlfn.TEXTSPLIT(M4,"-")} -> Muhammad | O4: Malik | P4: Male | Q4: IT
A5: Ayesha | B5: Shah | C5: Female | D5: Finance | E5: 45363 | F5: 60000 | G5: EMP-1004 | H5: =_xlfn.TEXTJOIN(" ",TRUE,A5,B5) -> Ayesha Shah | I5: =IF(C5="Male",_xlfn.TEXTJOIN(" S/o ",TRUE,A5,B5),_xlfn.TEXTJOIN(" W/o ",TRUE,A5,B5)) -> Ayesha W/o Shah | J5: =_xlfn.TEXTBEFORE(G5,"-") -> EMP | K5: =_xlfn.TEXTAFTER(G5,"-") -> 1004 | M5: Ayesha-Shah-Female-Finance | N5: {=_xlfn.TEXTSPLIT(M5,"-")} -> Ayesha | O5: Shah | P5: Female | Q5: Finance
A6: Hina | B6: Siddiqui | C6: Female | D6: Marketing | E6: 45235 | F6: 48000 | G6: EMP-1005 | H6: =_xlfn.TEXTJOIN(" ",TRUE,A6,B6) -> Hina Siddiqui | I6: =IF(C6="Male",_xlfn.TEXTJOIN(" S/o ",TRUE,A6,B6),_xlfn.TEXTJOIN(" W/o ",TRUE,A6,B6)) -> Hina W/o Siddiqui | J6: =_xlfn.TEXTBEFORE(G6,"-") -> EMP | K6: =_xlfn.TEXTAFTER(G6,"-") -> 1005 | M6: Hina-Siddiqui-Female-Marketing | N6: {=_xlfn.TEXTSPLIT(M6,"-")} -> Hina | O6: Siddiqui | P6: Female | Q6: Marketing
A7: Omar | B7: Raza | C7: Male | D7: Sales | E7: 44610 | F7: 55000 | G7: EMP-1006 | H7: =_xlfn.TEXTJOIN(" ",TRUE,A7,B7) -> Omar Raza | I7: =IF(C7="Male",_xlfn.TEXTJOIN(" S/o ",TRUE,A7,B7),_xlfn.TEXTJOIN(" W/o ",TRUE,A7,B7)) -> Omar S/o Raza | J7: =_xlfn.TEXTBEFORE(G7,"-") -> EMP | K7: =_xlfn.TEXTAFTER(G7,"-") -> 1006 | M7: Omar-Raza-Male-Sales | N7: {=_xlfn.TEXTSPLIT(M7,"-")} -> Omar | O7: Raza | P7: Male | Q7: Sales
A8: Fatima | B8: Butt | C8: Female | D8: HR | E8: 45465 | F8: 58000 | G8: EMP-1007 | H8: =_xlfn.TEXTJOIN(" ",TRUE,A8,B8) -> Fatima Butt | I8: =IF(C8="Male",_xlfn.TEXTJOIN(" S/o ",TRUE,A8,B8),_xlfn.TEXTJOIN(" W/o ",TRUE,A8,B8)) -> Fatima W/o Butt | J8: =_xlfn.TEXTBEFORE(G8,"-") -> EMP | K8: =_xlfn.TEXTAFTER(G8,"-") -> 1007 | M8: Fatima-Butt-Female-HR | N8: {=_xlfn.TEXTSPLIT(M8,"-")} -> Fatima | O8: Butt | P8: Female | Q8: HR
A9: Usman | B9: Iqbal | C9: Male | D9: IT | E9: 44453 | F9: 85000 | G9: EMP-1008 | H9: =_xlfn.TEXTJOIN(" ",TRUE,A9,B9) -> Usman Iqbal | I9: =IF(C9="Male",_xlfn.TEXTJOIN(" S/o ",TRUE,A9,B9),_xlfn.TEXTJOIN(" W/o ",TRUE,A9,B9)) -> Usman S/o Iqbal | J9: =_xlfn.TEXTBEFORE(G9,"-") -> EMP | K9: =_xlfn.TEXTAFTER(G9,"-") -> 1008 | M9: Usman-Iqbal-Male-IT | N9: {=_xlfn.TEXTSPLIT(M9,"-")} -> Usman | O9: Iqbal | P9: Male | Q9: IT
A10: Zain | B10: Sheikh | C10: Male | D10: Finance | E10: 45108 | F10: 62000 | G10: EMP-1009 | H10: =_xlfn.TEXTJOIN(" ",TRUE,A10,B10) -> Zain Sheikh | I10: =IF(C10="Male",_xlfn.TEXTJOIN(" S/o ",TRUE,A10,B10),_xlfn.TEXTJOIN(" W/o ",TRUE,A10,B10)) -> Zain S/o Sheikh | J10: =_xlfn.TEXTBEFORE(G10,"-") -> EMP | K10: =_xlfn.TEXTAFTER(G10,"-") -> 1009 | M10: Zain-Sheikh-Male-Finance | N10: {=_xlfn.TEXTSPLIT(M10,"-")} -> Zain | O10: Sheikh | P10: Male | Q10: Finance
A11: Noor | B11: Ahmed | C11: Female | D11: Marketing | E11: 45350 | F11: 50000 | G11: EMP-1010 | H11: =_xlfn.TEXTJOIN(" ",TRUE,A11,B11) -> Noor Ahmed | I11: =IF(C11="Male",_xlfn.TEXTJOIN(" S/o ",TRUE,A11,B11),_xlfn.TEXTJOIN(" W/o ",TRUE,A11,B11)) -> Noor W/o Ahmed | J11: =_xlfn.TEXTBEFORE(G11,"-") -> EMP | K11: =_xlfn.TEXTAFTER(G11,"-") -> 1010 | M11: Noor-Ahmed-Female-Marketing | N11: {=_xlfn.TEXTSPLIT(M11,"-")} -> Noor | O11: Ahmed | P11: Female | Q11: Marketing
A12: Ali | B12: Malik | C12: Male | D12: Sales | E12: 44906 | F12: 47000 | G12: EMP-1011 | H12: =_xlfn.TEXTJOIN(" ",TRUE,A12,B12) -> Ali Malik | I12: =IF(C12="Male",_xlfn.TEXTJOIN(" S/o ",TRUE,A12,B12),_xlfn.TEXTJOIN(" W/o ",TRUE,A12,B12)) -> Ali S/o Malik | J12: =_xlfn.TEXTBEFORE(G12,"-") -> EMP | K12: =_xlfn.TEXTAFTER(G12,"-") -> 1011 | M12: Ali-Malik-Male-Sales | N12: {=_xlfn.TEXTSPLIT(M12,"-")} -> Ali | O12: Malik | P12: Male | Q12: Sales
A13: Sara | B13: Khan | C13: Female | D13: HR | E13: 45032 | F13: 53000 | G13: EMP-1012 | H13: =_xlfn.TEXTJOIN(" ",TRUE,A13,B13) -> Sara Khan | I13: =IF(C13="Male",_xlfn.TEXTJOIN(" S/o ",TRUE,A13,B13),_xlfn.TEXTJOIN(" W/o ",TRUE,A13,B13)) -> Sara W/o Khan | J13: =_xlfn.TEXTBEFORE(G13,"-") -> EMP | K13: =_xlfn.TEXTAFTER(G13,"-") -> 1012 | M13: Sara-Khan-Female-HR
A14: Muhammad | B14: Shah | C14: Male | D14: IT | E14: 44494 | F14: 90000 | G14: EMP-1013 | I14: =IF(C14="Male",_xlfn.TEXTJOIN(" S/o ",TRUE,A14,B14),_xlfn.TEXTJOIN(" W/o ",TRUE,A14,B14)) -> Muhammad S/o Shah | J14: =_xlfn.TEXTBEFORE(G14,"-") -> EMP | K14: =_xlfn.TEXTAFTER(G14,"-") -> 1013
A15: Ayesha | B15: Ahmed | C15: Female | D15: Finance | E15: 45421 | F15: 64000 | G15: EMP-1014
A16: Hina | B16: Raza | C16: Female | D16: Marketing | E16: 44729 | F16: 51000 | G16: EMP-1015
A17: Omar | B17: Khan | C17: Male | D17: Sales | E17: 45190 | F17: 56000 | G17: EMP-1016
A18: Fatima | B18: Siddiqui | C18: Female | D18: HR | E18: 44533 | F18: 61000 | G18: EMP-1017
A19: Usman | B19: Malik | C19: Male | D19: IT | E19: 44659 | F19: 80000 | G19: EMP-1018
A20: Zain | B20: Ahmed | C20: Male | D20: Finance | E20: 45157 | F20: 67000 | G20: EMP-1019
A21: Noor | B21: Sheikh | C21: Female | D21: Marketing | E21: 45486 | F21: 54000 | G21: EMP-1020
A22: Ali | B22: Ahmed | C22: Male | D22: Sales | E22: 44281 | F22: 49000 | G22: EMP-1021
A23: Sara | B23: Butt | C23: Female | D23: HR | E23: 44895 | F23: 57000 | G23: EMP-1022
A24: Muhammad | B24: Ahmed | C24: Male | D24: IT | E24: 44933 | F24: 78000 | G24: EMP-1023
A25: Ayesha | B25: Malik | C25: Female | D25: Finance | E25: 44362 | F25: 70000 | G25: EMP-1024
A26: Hina | B26: Shah | C26: Female | D26: Marketing | E26: 44827 | F26: 52000 | G26: EMP-1025
... A31: Noor | B31: Malik | C31: Female | D31: Marketing | E31: 45217 | F31: 55000 | G31: EMP-1030

Sheet subtotal
A1: Order_ID | B1: Region | C1: Product | D1: Quantity | E1: Sales | G1: ORD-1013 | H1: South | I1: Mouse | J1: 7 | K1: 10500
A2: ORD-1001 | B2: South | C2: Laptop | D2: 2 | E2: 150000 | G2: ORD-1014 | H2: North | I2: Laptop | J2: 2 | K2: 150000
A3: ORD-1002 | B3: North | C3: Mouse | D3: 5 | E3: 7500 | G3: ORD-1015 | H3: East | I3: Monitor | J3: 1 | K3: 35000 | M3: Subtotal | N3: Arregate
A4: ORD-1003 | B4: East | C4: Keyboard | D4: 3 | E4: 12000 | G4: ORD-1016 | H4: West | I4: Keyboard | J4: 4 | K4: 16000 | M4: =SUBTOTAL(9,E2:E31) -> 572500 | N4: =_xlfn.AGGREGATE(9,6,E2:E31) -> 572500
A5: ORD-1004 | B5: West | C5: Monitor | D5: 2 | E5: 70000 | G5: ORD-1017 | H5: South | I5: Laptop | J5: 3 | K5: 225000 | N5: Vstack
A6: ORD-1005 | B6: South | C6: Mouse | D6: 4 | E6: 6000 | G6: ORD-1018 | H6: North | I6: Mouse | J6: 2 | K6: 3000 | M6: {=_xlfn.VSTACK(A1:E13,G1:K18)} -> Order_ID | N6: Region | O6: Product | P6: Quantity | Q6: Sales
A7: ORD-1006 | B7: North | C7: Laptop | D7: 1 | E7: 75000 | G7: ORD-1019 | H7: East | I7: Keyboard | J7: 6 | K7: 24000 | M7: ORD-1001 | N7: South | O7: Laptop | P7: 2 | Q7: 150000
A8: ORD-1007 | B8: East | C8: Monitor | D8: 3 | E8: 105000 | G8: ORD-1020 | H8: West | I8: Monitor | J8: 2 | K8: 70000 | M8: ORD-1002 | N8: North | O8: Mouse | P8: 5 | Q8: 7500
A9: ORD-1008 | B9: West | C9: Keyboard | D9: 5 | E9: 20000 | G9: ORD-1021 | H9: South | I9: Mouse | J9: 3 | K9: 4500 | M9: ORD-1003 | N9: East | O9: Keyboard | P9: 3 | Q9: 12000
A10: ORD-1009 | B10: South | C10: Laptop | D10: 1 | E10: 75000 | G10: ORD-1022 | H10: North | I10: Laptop | J10: 1 | K10: 75000 | M10: ORD-1004 | N10: West | O10: Monitor | P10: 2 | Q10: 70000
A11: ORD-1010 | B11: North | C11: Mouse | D11: 6 | E11: 9000 | G11: ORD-1023 | H11: East | I11: Monitor | J11: 4 | K11: 140000 | M11: ORD-1005 | N11: South | O11: Mouse | P11: 4 | Q11: 6000
A12: ORD-1011 | B12: East | C12: Keyboard | D12: 2 | E12: 8000 | G12: ORD-1024 | H12: West | I12: Keyboard | J12: 2 | K12: 8000 | M12: ORD-1006 | N12: North | O12: Laptop | P12: 1 | Q12: 75000
A13: ORD-1012 | B13: West | C13: Monitor | D13: 1 | E13: 35000 | G13: ORD-1025 | H13: South | I13: Laptop | J13: 2 | K13: 150000 | M13: ORD-1007 | N13: East | O13: Monitor | P13: 3 | Q13: 105000
G14: ORD-1026 | H14: North | I14: Mouse | J14: 4 | K14: 6000 | M14: ORD-1008 | N14: West | O14: Keyboard | P14: 5 | Q14: 20000
G15: ORD-1027 | H15: East | I15: Keyboard | J15: 3 | K15: 12000 | M15: ORD-1009 | N15: South | O15: Laptop | P15: 1 | Q15: 75000
G16: ORD-1028 | H16: West | I16: Monitor | J16: 5 | K16: 175000 | M16: ORD-1010 | N16: North | O16: Mouse | P16: 6 | Q16: 9000
G17: ORD-1029 | H17: South | I17: Mouse | J17: 5 | K17: 7500 | M17: ORD-1011 | N17: East | O17: Keyboard | P17: 2 | Q17: 8000
G18: ORD-1030 | H18: North | I18: Laptop | J18: 3 | K18: 225000 | M18: ORD-1012 | N18: West | O18: Monitor | P18: 1 | Q18: 35000
M19: ORD-1013 | N19: South | O19: Mouse | P19: 7 | Q19: 10500
M20: ORD-1014 | N20: North | O20: Laptop | P20: 2 | Q20: 150000
M21: ORD-1015 | N21: East | O21: Monitor | P21: 1 | Q21: 35000
M22: ORD-1016 | N22: West | O22: Keyboard | P22: 4 | Q22: 16000
M23: ORD-1017 | N23: South | O23: Laptop | P23: 3 | Q23: 225000
M24: ORD-1018 | N24: North | O24: Mouse | P24: 2 | Q24: 3000
M25: ORD-1019 | N25: East | O25: Keyboard | P25: 6 | Q25: 24000
M26: ORD-1020 | N26: West | O26: Monitor | P26: 2 | Q26: 70000
M27: ORD-1021 | N27: South | O27: Mouse | P27: 3 | Q27: 4500
M28: ORD-1022 | N28: North | O28: Laptop | P28: 1 | Q28: 75000
M29: ORD-1023 | N29: East | O29: Monitor | P29: 4 | Q29: 140000
M30: ORD-1024 | N30: West | O30: Keyboard | P30: 2 | Q30: 8000
... M36: ORD-1030 | N36: North | O36: Laptop | P36: 3 | Q36: 225000

Sheet advanced filter
A1: Order ID | B1: Product ID | C1: Product | D1: Category | E1: Quantity Sold | F1: Rate | G1: Sales | H1: Date | I1: State | J1: Ship Mode | K1: Segment | L1: Seller_ID
A2: 1743 | B2: PD-110 | C2: =_xlfn.XLOOKUP(B2,product!$A$2:$A$20,product!$B$2:$B$20) -> Laptop Stand | D2: =_xlfn.XLOOKUP(C2,product!$B$2:$B$20,product!$C$2:$C$20) -> Laptop Accessories | E2: 175 | F2: 500 | G2: 87500 | H2: 44562 | I2: Faisalabad | J2: First Class | K2: Home Office | L2: COM3737
A3: 1447 | B3: PD-107 | C3: =_xlfn.XLOOKUP(B3,product!$A$2:$A$20,product!$B$2:$B$20) -> SSD | D3: =_xlfn.XLOOKUP(C3,product!$B$2:$B$20,product!$C$2:$C$20) -> Internal Hardware | E3: 293 | F3: 9500 | G3: 2783500 | H3: 44563 | I3: Rawalpindi | J3: Standard Class | K3: Consumer | L3: COM6175
A4: 1802 | B4: PD-116 | C4: =_xlfn.XLOOKUP(B4,product!$A$2:$A$20,product!$B$2:$B$20) -> Wireless Router | D4: =_xlfn.XLOOKUP(C4,product!$B$2:$B$20,product!$C$2:$C$20) -> Network | E4: 177 | F4: 1350 | G4: 238950 | H4: 44564 | I4: Multan | J4: Second Class | K4: Home Office | L4: COM8842
A5: 1495 | B5: PD-104 | C5: =_xlfn.XLOOKUP(B5,product!$A$2:$A$20,product!$B$2:$B$20) -> Monitor | D5: =_xlfn.XLOOKUP(C5,product!$B$2:$B$20,product!$C$2:$C$20) -> Display | E5: 192 | F5: 1350 | G5: 259200 | H5: 44565 | I5: Gujranwala | J5: First Class | K5: Consumer | L5: COM2184
A6: 1570 | B6: PD-110 | C6: =_xlfn.XLOOKUP(B6,product!$A$2:$A$20,product!$B$2:$B$20) -> Laptop Stand | D6: =_xlfn.XLOOKUP(C6,product!$B$2:$B$20,product!$C$2:$C$20) -> Laptop Accessories | E6: 148 | F6: 500 | G6: 74000 | H6: 44566 | I6: Sialkot | J6: First Class | K6: Home Office | L6: COM3726
A7: 1822 | B7: PD-105 | C7: =_xlfn.XLOOKUP(B7,product!$A$2:$A$20,product!$B$2:$B$20) -> Graphics Card | D7: =_xlfn.XLOOKUP(C7,product!$B$2:$B$20,product!$C$2:$C$20) -> Internal Hardware | E7: 262 | F7: 12000 | G7: 3144000 | H7: 44567 | I7: Bahawalpur | J7: Standard Class | K7: Corporate | L7: COM3175
A8: 1699 | B8: PD-100 | C8: =_xlfn.XLOOKUP(B8,product!$A$2:$A$20,product!$B$2:$B$20) -> Keyboard | D8: =_xlfn.XLOOKUP(C8,product!$B$2:$B$20,product!$C$2:$C$20) -> Input Device | E8: 259 | F8: 800 | G8: 207200 | H8: 44568 | I8: Sargodha | J8: First Class | K8: Consumer | L8: COM7392
A9: 1492 | B9: PD-104 | C9: =_xlfn.XLOOKUP(B9,product!$A$2:$A$20,product!$B$2:$B$20) -> Monitor | D9: =_xlfn.XLOOKUP(C9,product!$B$2:$B$20,product!$C$2:$C$20) -> Display | E9: 232 | F9: 15000 | G9: 3480000 | H9: 44569 | I9: Karachi | J9: Standard Class | K9: Home Office | L9: COM3575
A10: 1670 | B10: PD-101 | C10: =_xlfn.XLOOKUP(B10,product!$A$2:$A$20,product!$B$2:$B$20) -> Mouse | D10: =_xlfn.XLOOKUP(C10,product!$B$2:$B$20,product!$C$2:$C$20) -> Input Device | E10: 153 | F10: 500 | G10: 76500 | H10: 44570 | I10: Hyderabad | J10: First Class | K10: Corporate | L10: COM7966
A11: 1244 | B11: PD-112 | C11: =_xlfn.XLOOKUP(B11,product!$A$2:$A$20,product!$B$2:$B$20) -> Headset | D11: =_xlfn.XLOOKUP(C11,product!$B$2:$B$20,product!$C$2:$C$20) -> Audio | E11: 192 | F11: 1500 | G11: 288000 | H11: 44571 | I11: Sukkur | J11: First Class | K11: Consumer | L11: COM1490 | N11: Product | O11: Category
A12: 1502 | B12: PD-102 | C12: =_xlfn.XLOOKUP(B12,product!$A$2:$A$20,product!$B$2:$B$20) -> Hard Drive | D12: =_xlfn.XLOOKUP(C12,product!$B$2:$B$20,product!$C$2:$C$20) -> Storage | E12: 116 | F12: 8000 | G12: 928000 | H12: 44572 | I12: Larkana | J12: Standard Class | K12: Corporate | L12: COM5769 | N12: Laptop Stand | O12: Laptop Accessories
A13: 1493 | B13: PD-104 | C13: =_xlfn.XLOOKUP(B13,product!$A$2:$A$20,product!$B$2:$B$20) -> Monitor | D13: =_xlfn.XLOOKUP(C13,product!$B$2:$B$20,product!$C$2:$C$20) -> Display | E13: 153 | F13: 15000 | G13: 2295000 | H13: 44573 | I13: Nawabshah | J13: Second Class | K13: Home Office | L13: COM8095
A14: 1987 | B14: PD-115 | C14: =_xlfn.XLOOKUP(B14,product!$A$2:$A$20,product!$B$2:$B$20) -> Speakers | D14: =_xlfn.XLOOKUP(C14,product!$B$2:$B$20,product!$C$2:$C$20) -> Audio | E14: 279 | F14: 5300 | G14: 1478700 | H14: 44574 | I14: Mirpur Khas | J14: First Class | K14: Corporate | L14: COM1606
A15: 1502 | B15: PD-114 | C15: =_xlfn.XLOOKUP(B15,product!$A$2:$A$20,product!$B$2:$B$20) -> Scanner | D15: =_xlfn.XLOOKUP(C15,product!$B$2:$B$20,product!$C$2:$C$20) -> Peripherals | E15: 286 | F15: 7600 | G15: 2173600 | H15: 44575 | I15: Faisalabad | J15: Standard Class | K15: Home Office | L15: COM7245
A16: 1821 | B16: PD-115 | C16: =_xlfn.XLOOKUP(B16,product!$A$2:$A$20,product!$B$2:$B$20) -> Speakers | D16: =_xlfn.XLOOKUP(C16,product!$B$2:$B$20,product!$C$2:$C$20) -> Audio | E16: 144 | F16: 5300 | G16: 763200 | H16: 44576 | I16: Rawalpindi | J16: Standard Class | K16: Corporate | L16: COM8968
A17: 1956 | B17: PD-105 | C17: =_xlfn.XLOOKUP(B17,product!$A$2:$A$20,product!$B$2:$B$20) -> Graphics Card | D17: =_xlfn.XLOOKUP(C17,product!$B$2:$B$20,product!$C$2:$C$20) -> Internal Hardware | E17: 180 | F17: 12000 | G17: 2160000 | H17: 44577 | I17: Multan | J17: First Class | K17: Home Office | L17: COM3737
A18: 1729 | B18: PD-113 | C18: =_xlfn.XLOOKUP(B18,product!$A$2:$A$20,product!$B$2:$B$20) -> Printer | D18: =_xlfn.XLOOKUP(C18,product!$B$2:$B$20,product!$C$2:$C$20) -> Peripherals | E18: 290 | F18: 11500 | G18: 3335000 | H18: 44578 | I18: Gujranwala | J18: Standard Class | K18: Corporate | L18: COM6175
A19: 1288 | B19: PD-117 | C19: =_xlfn.XLOOKUP(B19,product!$A$2:$A$20,product!$B$2:$B$20) -> Ethernet Cable | D19: =_xlfn.XLOOKUP(C19,product!$B$2:$B$20,product!$C$2:$C$20) -> Cables & Connectors | E19: 145 | F19: 600 | G19: 87000 | H19: 44579 | I19: Sialkot | J19: First Class | K19: Corporate | L19: COM8842
A20: 1309 | B20: PD-117 | C20: =_xlfn.XLOOKUP(B20,product!$A$2:$A$20,product!$B$2:$B$20) -> Ethernet Cable | D20: =_xlfn.XLOOKUP(C20,product!$B$2:$B$20,product!$C$2:$C$20) -> Cables & Connectors | E20: 149 | F20: 600 | G20: 89400 | H20: 44580 | I20: Bahawalpur | J20: Standard Class | K20: Corporate | L20: COM2184
A21: 1002 | B21: PD-115 | C21: =_xlfn.XLOOKUP(B21,product!$A$2:$A$20,product!$B$2:$B$20) -> Speakers | D21: =_xlfn.XLOOKUP(C21,product!$B$2:$B$20,product!$C$2:$C$20) -> Audio | E21: 206 | F21: 5300 | G21: 1091800 | H21: 44581 | I21: Sargodha | J21: Standard Class | K21: Home Office | L21: COM3726
A22: 1394 | B22: PD-118 | C22: =_xlfn.XLOOKUP(B22,product!$A$2:$A$20,product!$B$2:$B$20) -> Laptop Bag | D22: =_xlfn.XLOOKUP(C22,product!$B$2:$B$20,product!$C$2:$C$20) -> Laptop Accessories | E22: 110 | F22: 300 | G22: 33000 | H22: 44582 | I22: Karachi | J22: Standard Class | K22: Corporate | L22: COM3175
A23: 1049 | B23: PD-111 | C23: =_xlfn.XLOOKUP(B23,product!$A$2:$A$20,product!$B$2:$B$20) -> Cooling Pad | D23: =_xlfn.XLOOKUP(C23,product!$B$2:$B$20,product!$C$2:$C$20) -> Laptop Accessories | E23: 254 | F23: 650 | G23: 165100 | H23: 44583 | I23: Sukkur | J23: Second Class | K23: Consumer | L23: COM7392
A24: 1005 | B24: PD-109 | C24: =_xlfn.XLOOKUP(B24,product!$A$2:$A$20,product!$B$2:$B$20) -> Webcam | D24: =_xlfn.XLOOKUP(C24,product!$B$2:$B$20,product!$C$2:$C$20) -> Peripherals | E24: 203 | F24: 3500 | G24: 710500 | H24: 44584 | I24: Larkana | J24: First Class | K24: Consumer | L24: COM3575
... A366: 299 | B366: PD-101 | C366: =_xlfn.XLOOKUP(B366,product!$A$2:$A$20,product!$B$2:$B$20) -> Mouse | D366: =_xlfn.XLOOKUP(C366,product!$B$2:$B$20,product!$C$2:$C$20) -> Input Device | E366: 187 | F366: 3193 | G366: 597091 | H366: 44926 | I366: Sargodha | J366: First Class | K366: Consumer | L366: COM7245
